
Starting MurmurWall

Traceback (most recent call last):
  File "/home/pi/MurmurWall/Raspi/animation.py", line 576, in <module>
    main()
  File "/home/pi/MurmurWall/Raspi/animation.py", line 447, in main
    GPIO.setup(RELAY_PIN_1, GPIO.OUT)
RuntimeError: No access to /dev/mem.  Try running as root!

Starting MurmurWall

Traceback (most recent call last):
  File "/home/pi/MurmurWall/Raspi/animation.py", line 576, in <module>
    main()
  File "/home/pi/MurmurWall/Raspi/animation.py", line 447, in main
    GPIO.setup(RELAY_PIN_1, GPIO.OUT)
RuntimeError: No access to /dev/mem.  Try running as root!

Starting MurmurWall

Traceback (most recent call last):
  File "/home/pi/MurmurWall/Raspi/animation.py", line 576, in <module>
    main()
  File "/home/pi/MurmurWall/Raspi/animation.py", line 447, in main
    GPIO.setup(RELAY_PIN_1, GPIO.OUT)
RuntimeError: No access to /dev/mem.  Try running as root!

Starting MurmurWall

Traceback (most recent call last):
  File "/home/pi/MurmurWall/Raspi/animation.py", line 576, in <module>
    main()
  File "/home/pi/MurmurWall/Raspi/animation.py", line 447, in main
    GPIO.setup(RELAY_PIN_1, GPIO.OUT)
RuntimeError: No access to /dev/mem.  Try running as root!
/home/pi/MurmurWall/Raspi/animation.py:447: RuntimeWarning: This channel is already in use, continuing anyway.  Use GPIO.setwarnings(False) to disable warnings.
  GPIO.setup(RELAY_PIN_1, GPIO.OUT)
/home/pi/MurmurWall/Raspi/animation.py:448: RuntimeWarning: This channel is already in use, continuing anyway.  Use GPIO.setwarnings(False) to disable warnings.
  GPIO.setup(RELAY_PIN_2, GPIO.OUT)
/home/pi/MurmurWall/Raspi/animation.py:449: RuntimeWarning: This channel is already in use, continuing anyway.  Use GPIO.setwarnings(False) to disable warnings.
  GPIO.setup(RELAY_PIN_3, GPIO.OUT)
/home/pi/MurmurWall/Raspi/animation.py:450: RuntimeWarning: This channel is already in use, continuing anyway.  Use GPIO.setwarnings(False) to disable warnings.
  GPIO.setup(RELAY_PIN_4, GPIO.OUT)
/usr/local/lib/python2.7/dist-packages/requests/packages/urllib3/util/ssl_.py:90: InsecurePlatformWarning: A true SSLContext object is not available. This prevents urllib3 from configuring SSL appropriately and may cause certain SSL connections to fail. For more information, see https://urllib3.readthedocs.org/en/latest/security.html#insecureplatformwarning.
  InsecurePlatformWarning
